Workbook

Sheet Tabla dinámica 1

Sheet DASHBOARD
B2: SISTEMA INTELIGENTE JIT - CONTROL DE INVENTARIO Y ABASTECIMIENTO
B3: Gestion de Flota 260 Buses | Principios Logisticos Ballou | Repotenciado 2100 Refs
B4: Las formulas se alimentan de la hoja DATA (base de datos diaria) y DATA PENDIENTES (OC abiertas)
B6: NAVEGACION RAPIDA
B9: INDICADORES CLAVE DE RENDIMIENTO - KPI
B10: =COUNTA(DATA!B4:B2103) -> 1828 | E10: ='Tabla dinámica 1'!B10 -> 2067844421 | G10: 636 | I10: 1192 | K10: =COUNTA('DATA PENDIENTES'!B4:B2103) -> 264
B11: Total Referencias | E11: Valor Total Inventario ($) | G11: Productos Stock CERO | I11: Productos con Stock | K11: Ordenes Pendientes
B13: 1144 | E13: 335 | G13: 349 | I13: =IFERROR(AVERAGE(DATA!E4:E2103),0) -> 323.32652 | K13: =COUNTA('DATA PENDIENTES'!B4:B2103) -> 264
B14: Clase A (Alto Valor) | E14: Clase B (Medio) | G14: Clase C (Normal) | I14: Stock Promedio/Ref | K14: Items Pendientes Detalle
B16: SEMAFORO DE ALERTAS - SISTEMA JIT (Punto de Reorden Dinamico - Ballou Cap. 9)
B17: ='Tabla dinámica 1'!B2 -> 21471177 | E17: ='Tabla dinámica 1'!B3 -> 2.3342555e+08 | F17: ='Tabla dinámica 1'!B4 -> 50045141 | G17: ='Tabla dinámica 1'!B5 -> 153762018 | H17: ='Tabla dinámica 1'!B6 -> 1.4287297e+08 | I17: ='Tabla dinámica 1'!B7 -> 4.7733398e+08 | J17: ='Tabla dinámica 1'!B8 -> 1.6376702e+08 | L17: ='Tabla dinámica 1'!B9 -> 8.2516657e+08 | N17: =SUM(B17:M17) -> 2067844421
B18: CAJA | E18: CARROCERIA | F18: COMBUSTIBLE | G18: COMUNICACIONES | H18: ELECTRICIDAD | I18: LLANTAS | J18: LUBRICANTES | L18: PLATAFORMA | N18: TOTAL
B19: =COUNTIF('CONTROL INVENTARIO'!$Q$4:$Q$2103,"CRITICO") -> 632 | F19: =COUNTIF('CONTROL INVENTARIO'!$Q$4:$Q$2103,"REORDEN INMEDIATO") -> 303 | I19: =COUNTIF('CONTROL INVENTARIO'!$Q$4:$Q$2103,"PRECAUCION") -> 165 | L19: =COUNTIF('CONTROL INVENTARIO'!$Q$4:$Q$2103,"OPTIMO")+COUNTIF('CONTROL INVENTARIO'!$Q$4:$Q$2103,"EXCESO") -> 728
B20: CRITICO - STOCK CERO RIESGO PARADA DE FLOTA | F20: REORDEN INMEDIATO Stock <= Punto Reorden | I20: PROXIMO A MINIMO Revisar en 48 horas | L20: STOCK SEGURO Nivel Optimo JIT
B22: TOP 20 PRODUCTOS DE MAYOR VALOR EN INVENTARIO | K22: PRODUCTOS CRITICOS - STOCK CERO (RIESGO PARADA)
B23: # | C23: OC | D23: REFERENCIA | E23: DESCRIPCION | F23: PROVEEDOR | G23: STOCK | H23: COSTO UNIT. | I23: VALOR TOTAL | J23: ABC | K23: REFERENCIA | L23: DESCRIPCION | M23: PROVEEDOR | N23: CONSUMO | O23: CONS. DIARIO
B24: 1 | C24: =IFERROR('TOP 20 VALOR'!C4,"") | D24: =IFERROR('TOP 20 VALOR'!D4,"") -> 77101000 | E24: =IFERROR('TOP 20 VALOR'!E4,"") -> RIN RUEDA DE DISCO 8.25X22.5 CON AVELLAN | F24: =IFERROR('TOP 20 VALOR'!F4,"") -> LLANTAS REPUESTOS Y SERVICIO SAS | G24: =IFERROR('TOP 20 VALOR'!G4,"") -> 202 | H24: =IFERROR('TOP 20 VALOR'!H4,"") -> 1750000 | I24: =IFERROR('TOP 20 VALOR'!I4,"") -> 353500000 | J24: =IFERROR('TOP 20 VALOR'!J4,"") -> A | K24: =IFERROR('TOP 20 CERO'!C4,"") -> 2210101 | L24: =IFERROR('TOP 20 CERO'!D4,"") -> GRASA SHEEL GADUS S3 V220C | M24: =IFERROR('TOP 20 CERO'!E4,"") -> 800186960 | N24: =IFERROR('TOP 20 CERO'!F4,"") -> 213338.7 | O24: =IFERROR('TOP 20 CERO'!G4,"") -> 584.48959
B25: 2 | C25: =IFERROR('TOP 20 VALOR'!C5,"") -> SU114003 | D25: =IFERROR('TOP 20 VALOR'!D5,"") -> 7730306 | E25: =IFERROR('TOP 20 VALOR'!E5,"") -> RODAMIENTO CUBO RUEDA DE REMOLQUE | F25: =IFERROR('TOP 20 VALOR'!F5,"") -> VOLVO GROUP COLOMBIA S A S | G25: =IFERROR('TOP 20 VALOR'!G5,"") -> 60 | H25: =IFERROR('TOP 20 VALOR'!H5,"") -> 1849900 | I25: =IFERROR('TOP 20 VALOR'!I5,"") -> 110994000 | J25: =IFERROR('TOP 20 VALOR'!J5,"") -> A | K25: =IFERROR('TOP 20 CERO'!C5,"") -> 801702021 | L25: =IFERROR('TOP 20 CERO'!D5,"") -> AGAMIX | M25: =IFERROR('TOP 20 CERO'!E5,"") -> 901319175 | N25: =IFERROR('TOP 20 CERO'!F5,"") -> 87200 | O25: =IFERROR('TOP 20 CERO'!G5,"") -> 238.90411
B26: 3 | C26: =IFERROR('TOP 20 VALOR'!C6,"") -> SU115530 | D26: =IFERROR('TOP 20 VALOR'!D6,"") -> 77101008 | E26: =IFERROR('TOP 20 VALOR'!E6,"") -> LLANTA NUEVA RADIAL 295/80-R22.5 | F26: =IFERROR('TOP 20 VALOR'!F6,"") -> LLANTAS REPUESTOS Y SERVICIO SAS | G26: =IFERROR('TOP 20 VALOR'!G6,"") -> 46 | H26: =IFERROR('TOP 20 VALOR'!H6,"") -> 2354430 | I26: =IFERROR('TOP 20 VALOR'!I6,"") -> 108303780 | J26: =IFERROR('TOP 20 VALOR'!J6,"") -> A | K26: =IFERROR('TOP 20 CERO'!C6,"") -> 801702028 | L26: =IFERROR('TOP 20 CERO'!D6,"") -> OXIGENO | M26: =IFERROR('TOP 20 CERO'!E6,"") -> 901319175 | N26: =IFERROR('TOP 20 CERO'!F6,"") -> 31800 | O26: =IFERROR('TOP 20 CERO'!G6,"") -> 87.123288
B27: 4 | C27: =IFERROR('TOP 20 VALOR'!C7,"") -> SU114827 | D27: =IFERROR('TOP 20 VALOR'!D7,"") -> 13210008 | E27: =IFERROR('TOP 20 VALOR'!E7,"") -> ALTERNADOR | F27: =IFERROR('TOP 20 VALOR'!F7,"") -> INNOVATEQ S.A.S | G27: =IFERROR('TOP 20 VALOR'!G7,"") -> 51 | H27: =IFERROR('TOP 20 VALOR'!H7,"") -> 1487533 | I27: =IFERROR('TOP 20 VALOR'!I7,"") -> 75864183 | J27: =IFERROR('TOP 20 VALOR'!J7,"") -> A | K27: =IFERROR('TOP 20 CERO'!C7,"") -> 21100002 | L27: =IFERROR('TOP 20 CERO'!D7,"") -> CASQUILLO DE TAPA VALVULAS | M27: =IFERROR('TOP 20 CERO'!E7,"") -> 900315569 | N27: =IFERROR('TOP 20 CERO'!F7,"") -> 23653 | O27: =IFERROR('TOP 20 CERO'!G7,"") -> 64.80274
B28: 5 | C28: =IFERROR('TOP 20 VALOR'!C8,"") | D28: =IFERROR('TOP 20 VALOR'!D8,"") -> 20220003 | E28: =IFERROR('TOP 20 VALOR'!E8,"") -> ACEITE MOTOR MOBIL DELVAC MODERN 15W 40 | F28: =IFERROR('TOP 20 VALOR'!F8,"") -> ORGANIZACION TERPEL S.A. | G28: =IFERROR('TOP 20 VALOR'!G8,"") -> 1171.1 | H28: =IFERROR('TOP 20 VALOR'!H8,"") -> 56520.99 | I28: =IFERROR('TOP 20 VALOR'!I8,"") -> 66191731 | J28: =IFERROR('TOP 20 VALOR'!J8,"") -> A | K28: =IFERROR('TOP 20 CERO'!C8,"") -> 80120006 | L28: =IFERROR('TOP 20 CERO'!D8,"") -> FRANELA DE COLOR | M28: =IFERROR('TOP 20 CERO'!E8,"") -> 900449648 | N28: =IFERROR('TOP 20 CERO'!F8,"") -> 18937 | O28: =IFERROR('TOP 20 CERO'!G8,"") -> 51.882192
B29: 6 | C29: =IFERROR('TOP 20 VALOR'!C9,"") -> SU114003 | D29: =IFERROR('TOP 20 VALOR'!D9,"") -> 5100101 | E29: =IFERROR('TOP 20 VALOR'!E9,"") -> DISCO DE FRENO VENTILADO | F29: =IFERROR('TOP 20 VALOR'!F9,"") -> VOLVO GROUP COLOMBIA S A S | G29: =IFERROR('TOP 20 VALOR'!G9,"") -> 54 | H29: =IFERROR('TOP 20 VALOR'!H9,"") -> 1193464 | I29: =IFERROR('TOP 20 VALOR'!I9,"") -> 64447056 | J29: =IFERROR('TOP 20 VALOR'!J9,"") -> A | K29: =IFERROR('TOP 20 CERO'!C9,"") -> 20220002 | L29: =IFERROR('TOP 20 CERO'!D9,"") -> ACEITE MOTOR MOBIL M-DEL XHP 10W 40 | M29: =IFERROR('TOP 20 CERO'!E9,"") -> 830095213 | N29: =IFERROR('TOP 20 CERO'!F9,"") -> 15675.01 | O29: =IFERROR('TOP 20 CERO'!G9,"") -> 42.945233
B30: 7 | C30: =IFERROR('TOP 20 VALOR'!C10,"") | D30: =IFERROR('TOP 20 VALOR'!D10,"") -> 80200005 | E30: =IFERROR('TOP 20 VALOR'!E10,"") -> NVR -SREAMAX A8 | F30: =IFERROR('TOP 20 VALOR'!F10,"") -> COLOMBIA TELECOMUNICACIONES S.A E.S.P | G30: =IFERROR('TOP 20 VALOR'!G10,"") -> 7 | H30: =IFERROR('TOP 20 VALOR'!H10,"") -> 8725736 | I30: =IFERROR('TOP 20 VALOR'!I10,"") -> 61080152 | J30: =IFERROR('TOP 20 VALOR'!J10,"") -> A | K30: =IFERROR('TOP 20 CERO'!C10,"") -> 43000004 | L30: =IFERROR('TOP 20 CERO'!D10,"") -> ACEITE DIFERENCIAL MOBIL LUBE HD 85W140 | M30: =IFERROR('TOP 20 CERO'!E10,"") -> 830095213 | N30: =IFERROR('TOP 20 CERO'!F10,"") -> 13695 | O30: =IFERROR('TOP 20 CERO'!G10,"") -> 37.520548
B31: 8 | C31: =IFERROR('TOP 20 VALOR'!C11,"") -> SU114595 | D31: =IFERROR('TOP 20 VALOR'!D11,"") -> 5100200 | E31: =IFERROR('TOP 20 VALOR'!E11,"") -> JUEGO DE PASTILLAS DE DISCO DE FRENO | F31: =IFERROR('TOP 20 VALOR'!F11,"") -> COMERCONZA SAS | G31: =IFERROR('TOP 20 VALOR'!G11,"") -> 122 | H31: =IFERROR('TOP 20 VALOR'!H11,"") -> 500272 | I31: =IFERROR('TOP 20 VALOR'!I11,"") -> 61033184 | J31: =IFERROR('TOP 20 VALOR'!J11,"") -> A | K31: =IFERROR('TOP 20 CERO'!C11,"") -> 80130267-G | L31: =IFERROR('TOP 20 CERO'!D11,"") -> POLIURETANO VERDE | M31: =IFERROR('TOP 20 CERO'!E11,"") -> 900449648 | N31: =IFERROR('TOP 20 CERO'!F11,"") -> 12000 | O31: =IFERROR('TOP 20 CERO'!G11,"") -> 32.876712
B32: 9 | C32: =IFERROR('TOP 20 VALOR'!C12,"") -> SU114612 | D32: =IFERROR('TOP 20 VALOR'!D12,"") -> 2540131 | E32: =IFERROR('TOP 20 VALOR'!E12,"") -> ADBLUE ARLA 32 AUTOMOTRIZ | F32: =IFERROR('TOP 20 VALOR'!F12,"") -> HIDROTECNIK S A S | G32: =IFERROR('TOP 20 VALOR'!G12,"") -> 16174.9 | H32: =IFERROR('TOP 20 VALOR'!H12,"") -> 3094 | I32: =IFERROR('TOP 20 VALOR'!I12,"") -> 50045141 | J32: =IFERROR('TOP 20 VALOR'!J12,"") -> A | K32: =IFERROR('TOP 20 CERO'!C12,"") -> 2210102 | L32: =IFERROR('TOP 20 CERO'!D12,"") -> ACEITE MOTOR SHEEL RIMULA R5 LE 10 W 40 | M32: =IFERROR('TOP 20 CERO'!E12,"") -> 800186960 | N32: =IFERROR('TOP 20 CERO'!F12,"") -> 9347.991 | O32: =IFERROR('TOP 20 CERO'!G12,"") -> 25.610934
B33: 10 | C33: =IFERROR('TOP 20 VALOR'!C13,"") | D33: =IFERROR('TOP 20 VALOR'!D13,"") -> 20220008 | E33: =IFERROR('TOP 20 VALOR'!E13,"") -> BOMBA DE ACEITE MOTOR | F33: =IFERROR('TOP 20 VALOR'!F13,"") -> VOLVO GROUP COLOMBIA S A S | G33: =IFERROR('TOP 20 VALOR'!G13,"") -> 4 | H33: =IFERROR('TOP 20 VALOR'!H13,"") -> 11534730 | I33: =IFERROR('TOP 20 VALOR'!I13,"") -> 46138920 | J33: =IFERROR('TOP 20 VALOR'!J13,"") -> A | K33: =IFERROR('TOP 20 CERO'!C13,"") -> 80110144-R | L33: =IFERROR('TOP 20 CERO'!D13,"") -> EXTINTOR DE INCENDIO | M33: =IFERROR('TOP 20 CERO'!E13,"") -> 800105847 | N33: =IFERROR('TOP 20 CERO'!F13,"") -> 6145 | O33: =IFERROR('TOP 20 CERO'!G13,"") -> 16.835616
B34: 11 | C34: =IFERROR('TOP 20 VALOR'!C14,"") | D34: =IFERROR('TOP 20 VALOR'!D14,"") -> 43000003 | E34: =IFERROR('TOP 20 VALOR'!E14,"") -> ACEITE DIFERENCIAL MOBIL LUBE HD PLUS 85W140 | F34: =IFERROR('TOP 20 VALOR'!F14,"") -> ORGANIZACION TERPEL S.A. | G34: =IFERROR('TOP 20 VALOR'!G14,"") -> 451.07 | H34: =IFERROR('TOP 20 VALOR'!H14,"") -> 85083.15 | I34: =IFERROR('TOP 20 VALOR'!I14,"") -> 38378456 | J34: =IFERROR('TOP 20 VALOR'!J14,"") -> A | K34: =IFERROR('TOP 20 CERO'!C14,"") -> 80120180 | L34: =IFERROR('TOP 20 CERO'!D14,"") -> CATALIZADOR RAPIDO | M34: =IFERROR('TOP 20 CERO'!E14,"") -> 900449648 | N34: =IFERROR('TOP 20 CERO'!F14,"") -> 5588 | O34: =IFERROR('TOP 20 CERO'!G14,"") -> 15.309589
B35: 12 | C35: =IFERROR('TOP 20 VALOR'!C15,"") | D35: =IFERROR('TOP 20 VALOR'!D15,"") -> 43000006 | E35: =IFERROR('TOP 20 VALOR'!E15,"") -> ACEITE CAJA MOBIL ATF DELVAC DRUM | F35: =IFERROR('TOP 20 VALOR'!F15,"") -> ORGANIZACION TERPEL S.A. | G35: =IFERROR('TOP 20 VALOR'!G15,"") -> 236.31 | H35: =IFERROR('TOP 20 VALOR'!H15,"") -> 156917.6 | I35: =IFERROR('TOP 20 VALOR'!I15,"") -> 37081198 | J35: =IFERROR('TOP 20 VALOR'!J15,"") -> A | K35: =IFERROR('TOP 20 CERO'!C15,"") -> 77101027-R | L35: =IFERROR('TOP 20 CERO'!D15,"") -> LLANTA REENCAUCHADA RADIAL 295/80-R22.5 | M35: =IFERROR('TOP 20 CERO'!E15,"") -> 900268222 | N35: =IFERROR('TOP 20 CERO'!F15,"") -> 5367 | O35: =IFERROR('TOP 20 CERO'!G15,"") -> 14.70411
... B43: 20 | C43: =IFERROR('TOP 20 VALOR'!C23,"") -> SU111857 | D43: =IFERROR('TOP 20 VALOR'!D23,"") -> 7260200 | E43: =IFERROR('TOP 20 VALOR'!E23,"") -> FUELLE NEUMATICO DELANTERO | F43: =IFERROR('TOP 20 VALOR'!F23,"") -> VOLVO GROUP COLOMBIA S A S | G43: =IFERROR('TOP 20 VALOR'!G23,"") -> 19 | H43: =IFERROR('TOP 20 VALOR'!H23,"") -> 690200 | I43: =IFERROR('TOP 20 VALOR'!I23,"") -> 13113800 | J43: =IFERROR('TOP 20 VALOR'!J23,"") -> A | K43: =IFERROR('TOP 20 CERO'!C23,"") -> 4370100 | L43: =IFERROR('TOP 20 CERO'!D23,"") -> ACEITE CAJA SHEEL ATF S4 HDX | M43: =IFERROR('TOP 20 CERO'!E23,"") -> 800186960 | N43: =IFERROR('TOP 20 CERO'!F23,"") -> 1980 | O43: =IFERROR('TOP 20 CERO'!G23,"") -> 5.4246575
B45: PRINCIPIOS LOGISTICOS APLICADOS (Ballou - Logistica: Cadena de Suministro 5ta Ed.)
B46: Clasificacion ABC (Pareto 80/20) | F46: Productos A (alto valor), B (medio), C (bajo). Clase A = control estricto. | L46: ="A:"&COUNTIF(DATA!M4:M2103,"A")&" | B:"&COUNTIF(DATA!M4:M2103,"B")&" | C:"&COUNTIF(DATA!M4:M2103,"C") -> A:1144 | B:335 | C:349
B47: Punto de Reorden (ROP) | F47: ROP = Consumo Diario x Lead Time + Stock Seguridad. | L47: Formula en CONTROL INVENTARIO
B48: Just In Time (JIT) | F48: Minimizar inventario manteniendo disponibilidad. | L48: Aplicado en todas las formulas
B49: EOQ - Cantidad Economica | F49: Equilibra costos de ordenar vs. mantener inventario. | L49: ="Total refs: "&COUNTA(DATA!B4:B2103) -> Total refs: 1828
B50: Stock de Seguridad | F50: Buffer para variabilidad en demanda y lead time. | L50: ="Refs sin stock: "&COUNTIF(DATA!E4:E2103,0) -> Refs sin stock: 632
B51: Rotacion de Inventario | F51: Consumo / Stock Promedio. Mayor rotacion = mejor gestion. | L51: ="Valor inv: $"&TEXT(SUM('CONTROL INVENTARIO'!J4:J2103),"#,##0") -> Valor inv: $2.067.844.421
B54: LEYENDA DE COLORES - FORMATO CONDICIONAL (Cuando Pedir)
B55: ROJO - CRITICO | F55: Stock = 0 o Stock < Punto de Reorden. PEDIR INMEDIATAMENTE.
B56: NARANJA - REORDEN | F56: Stock en punto de reorden. Generar OC en 24 horas.
B57: AMARILLO - PRECAUCION | F57: Stock entre 1x y 2x del punto de reorden. Monitorear.
...

Sheet DATA
B1: BASE DE DATOS DE INVENTARIO - DESCARGA DIARIA MAINSAVER
B2: Pegue aqui los datos de Mainsaver | Las hojas CONTROL INVENTARIO, DASHBOARD, TOP 20 se actualizan automaticamente
B3: REFERENCIA | C3: DESCRIPCION | D3: PARTE FABRICANTE | E3: STOCK ACTUAL | F3: COSTO UNITARIO | G3: TOTAL STOCK | H3: CUENTA | I3: PUNTO PEDIDO | J3: MINIMO | K3: MAXIMO | L3: UM EMISION | M3: CLASE ABC | N3: USO ANNO | O3: USO ANNO ANT. | P3: LEAD TIME PROM. | Q3: ROTACION ANNO | R3: ROTACION ANT. | S3: QUIEBRES ANNO | T3: QUIEBRES ANT. | U3: COSTO PROM. | V3: ULTIMO COSTO | W3: NIT PROVEEDOR | X3: BODEGA
B4: 12110002 | C4: TORNILLO FIJACION TAPAVALVULAS | D4: 3169658 | E4: 6 | F4: 92885.63 | G4: =F4*E4 -> 557313.78 | H4: PLATAFORMA | I4: 3 | J4: 5 | K4: 10 | L4: UND | M4: A | N4: 125 | O4: 0 | P4: 0 | Q4: 1 | R4: 0 | S4: 8 | T4: 0 | U4: 92885.6 | V4: 92361.04 | W4: 900315569 | X4: SU01F0303
B5: 12110003 | C5: PERNO BOLA | D5: 20501055 | E5: 3 | F5: 26069.17 | G5: =F5*E5 -> 78207.51 | H5: PLATAFORMA | I5: 0 | J5: 0 | K5: 0 | L5: UND | M5: C | N5: 5 | O5: 0 | P5: 0 | Q5: 0 | R5: 0 | S5: 0 | T5: 0 | U5: 26069.2 | V5: 26517.51 | W5: 900315569 | X5: SU01F0204
B6: 12110004 | C6: TUERCA HEXAGONAL | D6: 60111964 | E6: 4 | F6: 45754.34 | G6: =F6*E6 -> 183017.36 | H6: PLATAFORMA | I6: 0 | J6: 0 | K6: 0 | L6: UND | M6: C | N6: 4 | O6: 0 | P6: 0 | Q6: 0 | R6: 0 | S6: 0 | T6: 0 | U6: 45754.3 | V6: 45889.39 | W6: 900315569 | X6: SU01F0203
B7: 12110005 | C7: ANILO TORICO | D7: 944364 | E7: 5 | F7: 2620.185 | G7: =F7*E7 -> 13100.925 | H7: PLATAFORMA | I7: 0 | J7: 0 | K7: 0 | L7: UND | M7: C | N7: 1 | O7: 0 | P7: 0 | Q7: 0 | R7: 0 | S7: 0 | T7: 0 | U7: 2620.18 | V7: 2620.185 | W7: 900315569 | X7: SU01A0202
B8: 12110006 | C8: ANILLO RETEN CAJA INTERMEDIA | D8: 20526428 | E8: 8 | F8: 12974.52 | G8: =F8*E8 -> 103796.16 | H8: PLATAFORMA | I8: 0 | J8: 0 | K8: 0 | L8: UND | M8: A | N8: 65 | O8: 0 | P8: 0 | Q8: 0 | R8: 0 | S8: 8 | T8: 0 | U8: 12974.5 | V8: 12974.52 | W8: 900315569 | X8: SU01F0202
B9: 12110007 | C9: CASQUETE ARBOL DE LEVAS | D9: 20503200 | E9: 6 | F9: 132652.4 | G9: =F9*E9 -> 795914.4 | H9: PLATAFORMA | I9: 0 | J9: 0 | K9: 0 | L9: UND | M9: C | N9: 4 | O9: 0 | P9: 0 | Q9: 0 | R9: 0 | S9: 2 | T9: 0 | U9: 132652 | V9: 119312 | W9: 900315569 | X9: SU01F0203
B10: 12110008 | C10: MANGUITO INYECTOR (CAMISILLA) | D10: 21351717 | E10: 87 | F10: 121057.9 | G10: =F10*E10 -> 10532037 | H10: PLATAFORMA | I10: 60 | J10: 50 | K10: 100 | L10: UND | M10: A | N10: 3631 | O10: 0 | P10: 0 | Q10: 0 | R10: 0 | S10: 3 | T10: 0 | U10: 121058 | V10: 120069.4 | W10: 900315569 | X10: SU01F0201
B11: 12110009 | C11: ANILLO TORICO 26,2x3 mm | D11: 949721 | E11: 9 | F11: 12783.38 | G11: =F11*E11 -> 115050.42 | H11: PLATAFORMA | I11: 5 | J11: 5 | K11: 10 | L11: UND | M11: A | N11: 125 | O11: 0 | P11: 0 | Q11: 0 | R11: 0 | S11: 6 | T11: 0 | U11: 12783.4 | V11: 10863.41 | W11: 900315569 | X11: SU01F0202
B12: 12110010 | C12: JUNTA DE CULATA | D12: 3099100 | E12: 4 | F12: 1148356 | G12: =F12*E12 -> 4593424 | H12: PLATAFORMA | I12: 1 | J12: 1 | K12: 2 | L12: UND | M12: A | N12: 40 | O12: 0 | P12: 0 | Q12: 0 | R12: 0 | S12: 13 | T12: 0 | U12: 1148356 | V12: 1148356 | W12: 900315569 | X12: SU01E0107
B13: 12110011 | C13: CASQUETE ARBOL DE LEVAS | D13: 276630 | E13: 0 | F13: 107001.6 | G13: =F13*E13 -> 0 | H13: PLATAFORMA | I13: 0 | J13: 6 | K13: 0 | L13: UND | M13: C | N13: 102 | O13: 0 | P13: 0 | Q13: 0 | R13: 0 | S13: 8 | T13: 0 | U13: 107002 | V13: 108306.7 | W13: 900315569 | X13: SU01F0203
B14: 12110012 | C14: TAPA BANCADA ARBOL DE LEVAS | D14: 3165309 | E14: 0 | F14: 11987543 | G14: =F14*E14 -> 0 | H14: PLATAFORMA | I14: 0 | J14: 0 | K14: 0 | L14: UND | M14: A | N14: 2 | O14: 0 | P14: 0 | Q14: 0 | R14: 0 | S14: 2 | T14: 0 | U14: 12000000 | V14: 11987543 | W14: 900315569 | X14: SU01E0107
B15: 12110013 | C15: RETEN MOLDURA TAPA DE DISTRIBUCIÓN | D15: 20714247 | E15: 11 | F15: 76313.15 | G15: =F15*E15 -> 839444.65 | H15: PLATAFORMA | I15: 1 | J15: 1 | K15: 2 | L15: UND | M15: A | N15: 20 | O15: 0 | P15: 0 | Q15: 0 | R15: 0 | S15: 6 | T15: 0 | U15: 76313.2 | V15: 65972.17 | W15: 900315569 | X15: SU01F0202
... B43: 12130022 | C43: CAPÓ (CARTER SECO) | D43: 21704040 | E43: 0 | F43: 522.75 | G43: =F43*E43 -> 0 | H43: PLATAFORMA | I43: 0 | J43: 0 | K43: 0 | L43: UND | M43: C | N43: 0 | O43: 0 | P43: 0 | Q43: 0 | R43: 0 | S43: 0 | T43: 0 | U43: 522.75 | V43: 0 | W43: 900315569 | X43: SU01A0202
B44: 12130022-R | C44: CAPÓ (CARTER SECO) | D44: 21704040 | E44: 0 | F44: 181594 | G44: =F44*E44 -> 0 | H44: PLATAFORMA | I44: 0 | J44: 0 | K44: 0 | L44: UND | M44: A | N44: 43 | O44: 0 | P44: 0 | Q44: 0 | R44: 0 | S44: 43 | T44: 0 | U44: 181594 | V44: 181594 | W44: 901327111 | X44: SU01C0203
B45: 12130023 | C45: DEPOSITO ACEITE (CARTER DE FILTROS) | D45: 23416531 | E45: 0 | F45: 1933.5 | G45: =F45*E45 -> 0 | H45: PLATAFORMA | I45: 0 | J45: 0 | K45: 0 | L45: UND | M45: B | N45: 0 | O45: 0 | P45: 0 | Q45: 0 | R45: 0 | S45: 0 | T45: 0 | U45: 1933.5 | V45: 0 | W45: 900315569 | X45: SU01A0202
B46: 12130023-R | C46: DEPOSITO ACEITE (CARTER DE FILTROS) | D46: 23416531 | E46: 1 | F46: 214021.5 | G46: =F46*E46 -> 214021.5 | H46: PLATAFORMA | I46: 0 | J46: 0 | K46: 0 | L46: UND | M46: C | N46: 1 | O46: 0 | P46: 0 | Q46: 0 | R46: 0 | S46: 1 | T46: 0 | U46: 214022 | V46: 214021.5 | W46: 901327111 | X46: SU01A0202
B47: 12140000 | C47: KIT DE RETENES DISTRIBUCIÓN | D47: 85104153 | E47: 4 | F47: 612221.8 | G47: =F47*E47 -> 2448887.2 | H47: PLATAFORMA | I47: 2 | J47: 2 | K47: 4 | L47: UND | M47: A | N47: 65 | O47: 0 | P47: 0 | Q47: 0 | R47: 0 | S47: 25 | T47: 0 | U47: 612222 | V47: 612221.8 | W47: 900315569 | X47: SU01F0203
B48: 12140001 | C48: ARANDELA AXIAL DE DISTRIBUCIÓN | D48: 8170220 | E48: 0 | F48: 88909 | G48: =F48*E48 -> 0 | H48: PLATAFORMA | I48: 0 | J48: 0 | K48: 0 | L48: UND | M48: C | N48: 20 | O48: 0 | P48: 0 | Q48: 0 | R48: 0 | S48: 3 | T48: 0 | U48: 88909 | V48: 89150.93 | W48: 900315569 | X48: SU01F0203
B49: 12140002 | C49: ARANDELA DE PRESIÓN DISTRIBUCIÓN | D49: 3184865 | E49: 0 | F49: 84838.65 | G49: =F49*E49 -> 0 | H49: PLATAFORMA | I49: 0 | J49: 0 | K49: 0 | L49: UND | M49: A | N49: 20 | O49: 0 | P49: 0 | Q49: 0 | R49: 0 | S49: 3 | T49: 0 | U49: 84838.6 | V49: 86790.27 | W49: 900315569 | X49: SU01F0203
B50: 12140003 | C50: RETENEDOR CIGÜEÑAL TRASERO | D50: 24817250 | E50: 3 | F50: 451909.4 | G50: =F50*E50 -> 1355728.2 | H50: PLATAFORMA | I50: 2 | J50: 1 | K50: 4 | L50: UND | M50: A | N50: 49 | O50: 0 | P50: 0 | Q50: 1 | R50: 0 | S50: 12 | T50: 0 | U50: 451909 | V50: 451909.4 | W50: 900315569 | X50: SU01F0203
B51: 12140004 | C51: JUNTA CHAPA DE DISTRIBUCIÓN | D51: 20489341 | E51: 4 | F51: 92361.04 | G51: =F51*E51 -> 369444.16 | H51: PLATAFORMA | I51: 1 | J51: 1 | K51: 2 | L51: UND | M51: A | N51: 39 | O51: 0 | P51: 0 | Q51: 0 | R51: 0 | S51: 16 | T51: 0 | U51: 92361 | V51: 92361.04 | W51: 900315569 | X51: SU01F0202
B52: 12140005 | C52: JUNTA MEDIA TAPA DE DISTRIBUCION | D52: 3830184 | E52: 4 | F52: 50138.85 | G52: =F52*E52 -> 200555.4 | H52: PLATAFORMA | I52: 2 | J52: 2 | K52: 6 | L52: UND | M52: A | N52: 75 | O52: 0 | P52: 0 | Q52: 0 | R52: 0 | S52: 26 | T52: 0 | U52: 50138.9 | V52: 50138.85 | W52: 900315569 | X52: SU01F0202
B53: 12140006 | C53: JUNTA MEDIA TAPA DE DISTRIBUCION | D53: 20509433 | E53: 4 | F53: 36944.42 | G53: =F53*E53 -> 147777.68 | H53: PLATAFORMA | I53: 2 | J53: 1 | K53: 4 | L53: UND | M53: A | N53: 77 | O53: 0 | P53: 0 | Q53: 0 | R53: 0 | S53: 22 | T53: 0 | U53: 36944.4 | V53: 36944.42 | W53: 900315569 | X53: SU01F0202
B54: 12140007 | C54: RETENEDOR CIGUEÑAL DELANTERO | D54: 21347087 | E54: 5 | F54: 360383.4 | G54: =F54*E54 -> 1801917 | H54: PLATAFORMA | I54: 1 | J54: 0 | K54: 3 | L54: UND | M54: C | N54: 10 | O54: 0 | P54: 0 | Q54: 0 | R54: 0 | S54: 2 | T54: 0 | U54: 360383 | V54: 376936.7 | W54: 900315569 | X54: SU01F0203
B55: 12220007 | C55: TAPON MAGNETICO CARTER MOTOR | D55: 949175 | E55: 2 | F55: 70010.96 | G55: =F55*E55 -> 140021.92 | H55: PLATAFORMA | I55: 0 | J55: 0 | K55: 0 | L55: UND | M55: C | N55: 34 | O55: 0 | P55: 0 | Q55: 1 | R55: 0 | S55: 2 | T55: 0 | U55: 70011 | V55: 74801.57 | W55: 900315569 | X55: SU01F0304
B56: 12220008 | C56: TAPON MAGNETICO CARTER | D56: 20556987 | E56: 0 | F56: 0 | G56: =F56*E56 -> 0 | H56: PLATAFORMA | I56: 0 | J56: 0 | K56: 0 | L56: UND | M56: A | N56: 0 | O56: 0 | P56: 0 | Q56: 0 | R56: 0 | S56: 0 | T56: 0 | U56: 0 | V56: 0 | W56: 900315569 | X56: SU01C0203
B57: 12220009 | C57: SILICONA ULTRA GREY LOCTITE 300 ML | E57: 1 | F57: 143076.1 | G57: =F57*E57 -> 143076.1 | H57: PLATAFORMA | I57: 2 | J57: 2 | K57: 3 | L57: UND | M57: A | N57: 111 | O57: 0 | P57: 0 | Q57: 2 | R57: 0 | S57: 7 | T57: 0 | U57: 143076 | V57: 143076.1 | W57: 811025549 | X57: SU01E0304
B58: 12220010 | C58: ANILLO RETEN TUBO ACEITE | D58: 1677370 | E58: 13 | F58: 8480.923 | G58: =F58*E58 -> 110252 | H58: PLATAFORMA | I58: 10 | J58: 4 | K58: 20 | L58: UND | M58: A | N58: 196 | O58: 0 | P58: 0 | Q58: 0 | R58: 0 | S58: 8 | T58: 0 | U58: 8480.92 | V58: 8224.53 | W58: 900315569 | X58: SU01F0202
B59: 12220011 | C59: MANGUERA BAYONETA DE ACEITE | D59: 8149606 | E59: 1 | F59: 132911.1 | G59: =F59*E59 -> 132911.1 | H59: PLATAFORMA | I59: 1 | J59: 1 | K59: 3 | L59: UND | M59: A | N59: 18 | O59: 0 | P59: 0 | Q59: 1 | R59: 0 | S59: 8 | T59: 0 | U59: 132911 | V59: 132911.1 | W59: 900315569 | X59: SU01F0202
B60: 12220012 | C60: JUEGO DE RETENES CARTER DE ACEITE | D60: 85104152 | E60: 4 | F60: 1142638 | G60: =F60*E60 -> 4570552 | H60: PLATAFORMA | I60: 2 | J60: 2 | K60: 4 | L60: UND | M60: A | N60: 68 | O60: 0 | P60: 0 | Q60: 0 | R60: 0 | S60: 26 | T60: 0 | U60: 1142638 | V60: 1142638 | W60: 900315569 | X60: SU01F0202
B61: 12220013 | C61: LISTON DE GOMA | D61: 8192235 | E61: 9 | F61: 102916.6 | G61: =F61*E61 -> 926249.4 | H61: PLATAFORMA | I61: 6 | J61: 6 | K61: 12 | L61: M | M61: A | N61: 240 | O61: 0 | P61: 0 | Q61: 0 | R61: 0 | S61: 19 | T61: 0 | U61: 102917 | V61: 102916.6 | W61: 900315569 | X61: SU01F0202
B62: 12220014 | C62: SILICONA ULTRA GREY LOCTITE 50 ML | D62: 6581 | E62: 9 | F62: 19456.5 | G62: =F62*E62 -> 175108.5 | H62: PLATAFORMA | I62: 10 | J62: 5 | K62: 20 | L62: UND | M62: A | N62: 270 | O62: 0 | P62: 0 | Q62: 1 | R62: 0 | S62: 13 | T62: 0 | U62: 19456.5 | V62: 19456.5 | W62: 900057383 | X62: SU01E0304
B63: 12330003 | C63: TUBO PLASTICO DE COMBUSTIBLE 12MM | D63: 980833 | E63: 5 | F63: 19648.68 | G63: =F63*E63 -> 98243.4 | H63: PLATAFORMA | I63: 0 | J63: 0 | K63: 0 | L63: M | M63: C | N63: 40 | O63: 0 | P63: 0 | Q63: 0 | R63: 0 | S63: 0 | T63: 0 | U63: 19648.7 | V63: 5.32 | W63: 900315569 | X63: SU01A0203
B64: 12330004 | C64: ABRAZADERA ENCAUCHETADA 1 1/2" #40 | D64: 101030007 | E64: 8 | F64: 4385.15 | G64: =F64*E64 -> 35081.2 | H64: PLATAFORMA | I64: 4 | J64: 4 | K64: 8 | L64: UND | M64: A | N64: 451 | O64: 0 | P64: 0 | Q64: 0 | R64: 0 | S64: 2 | T64: 0 | U64: 4385.15 | V64: 4385.15 | W64: 826003816 | X64: SU01D0303
B65: 12330005 | C65: VALVULA DE AIREACION (DESFOGUE TANQUE COMB.) | D65: 20572888 | E65: 0 | F65: 114568.5 | G65: =F65*E65 -> 0 | H65: PLATAFORMA | I65: 0 | J65: 0 | K65: 0 | L65: UND | M65: A | N65: 1 | O65: 0 | P65: 0 | Q65: 0 | R65: 0 | S65: 1 | T65: 0 | U65: 114568 | V65: 114568.5 | W65: 900315569 | X65: SU01C0204
B66: 12330006 | C66: TUBO DESFOGUE TANQUE COMBUSTIBLE | D66: 980832 | E66: 0 | F66: 0 | G66: =F66*E66 -> 0 | H66: PLATAFORMA | I66: 0 | J66: 0 | K66: 0 | L66: UND | M66: A | N66: 0 | O66: 0 | P66: 0 | Q66: 0 | R66: 0 | S66: 0 | T66: 0 | U66: 0 | V66: 0 | W66: 900315569 | X66: SU01C0204
B67: 12330007 | C67: INYECTOR BOMBA | D67: 20569291 | E67: 0 | F67: 3278355 | G67: =F67*E67 -> 0 | H67: PLATAFORMA | I67: 0 | J67: 0 | K67: 0 | L67: UND | M67: A | N67: 8 | O67: 0 | P67: 0 | Q67: 0 | R67: 0 | S67: 3 | T67: 0 | U67: 3278355 | V67: 3278355 | W67: 900315569 | X67: SU01B0202
...

Sheet DATA PENDIENTES
B1: CONTROL DE MATERIALES PENDIENTES POR LLEGAR - ORDENES DE COMPRA
B2: Ultima actualizacion: 07/04/2026 | Pegue aqui datos de OC pendientes
B3: ORDEN COMPRA | C3: DESCRIPCION | D3: QTY ORDENADA | E3: UM | F3: QTY RECIBIDA | G3: QTY PENDIENTE | H3: COSTO UNIT. | I3: PROVEEDOR | J3: PARTE FABRICANTE | K3: COMPRADOR | L3: MAINSAVER | M3: FECHA PROMESA | N3: FECHA REQUERIDA | O3: VALOR IMPUESTO | P3: VALOR PENDIENTE | Q3: DIAS RETRASO | R3: ESTADO | S3: CUMPLIMIENTO | T3: PRIORIDAD
B4: SU114003 | C4: RUEDA SENSORA | D4: 312 | E4: UND | F4: 170 | G4: 142 | H4: 103221 | I4: VOLVO GROUP COLOMBIA S A S | J4: 22537018 | K4: CRISTHIAN BENITEZ | L4: 7640210 | M4: 46326 | N4: 46265 | O4: 6118941 | P4: =IFERROR(G4*H4,0) -> 14657382 | Q4: =IFERROR(IF(N4="","",MAX(TODAY()-N4,0)),0) -> 0 | R4: =IF(B4="","",IF(G4=0,"COMPLETO",IF(G4<=D4*0.1,"CASI COMPLETO","PENDIENTE"))) -> PENDIENTE | S4: =IF(B4="","",IFERROR(F4/D4,0)) -> 0.54487179 | T4: =IF(B4="","",IF(Q4>30,"CRITICO",IF(Q4>7,"URGENTE","NORMAL"))) -> NORMAL
B5: SU114003 | C5: DISCO DE FRENO VENTILADO | D5: 460 | E5: UND | F5: 280 | G5: 180 | H5: 1002911 | I5: VOLVO GROUP COLOMBIA S A S | J5: 21575071 | K5: CRISTHIAN BENITEZ | L5: 5100101 | M5: 46326 | N5: 46265 | O5: 87654421 | P5: =IFERROR(G5*H5,0) -> 180523980 | Q5: =IFERROR(IF(N5="","",MAX(TODAY()-N5,0)),0) -> 0 | R5: =IF(B5="","",IF(G5=0,"COMPLETO",IF(G5<=D5*0.1,"CASI COMPLETO","PENDIENTE"))) -> PENDIENTE | S5: =IF(B5="","",IFERROR(F5/D5,0)) -> 0.60869565 | T5: =IF(B5="","",IF(Q5>30,"CRITICO",IF(Q5>7,"URGENTE","NORMAL"))) -> NORMAL
B6: SU114003 | C6: DISCO DE FRENO SOLIDO | D6: 160 | E6: UND | F6: 110 | G6: 50 | H6: 1140000 | I6: VOLVO GROUP COLOMBIA S A S | J6: 3092710 | K6: CRISTHIAN BENITEZ | L6: 5100100 | M6: 46326 | N6: 46265 | O6: 34656000 | P6: =IFERROR(G6*H6,0) -> 57000000 | Q6: =IFERROR(IF(N6="","",MAX(TODAY()-N6,0)),0) -> 0 | R6: =IF(B6="","",IF(G6=0,"COMPLETO",IF(G6<=D6*0.1,"CASI COMPLETO","PENDIENTE"))) -> PENDIENTE | S6: =IF(B6="","",IFERROR(F6/D6,0)) -> 0.6875 | T6: =IF(B6="","",IF(Q6>30,"CRITICO",IF(Q6>7,"URGENTE","NORMAL"))) -> NORMAL
B7: SU114003 | C7: RODAMIENTO CUBO RUEDA DE REMOLQUE | D7: 360 | E7: UND | F7: 210 | G7: 150 | H7: 1554538 | I7: VOLVO GROUP COLOMBIA S A S | J7: 21036050 | K7: CRISTHIAN BENITEZ | L7: 7730306 | M7: 46326 | N7: 46265 | O7: 106000000 | P7: =IFERROR(G7*H7,0) -> 233180700 | Q7: =IFERROR(IF(N7="","",MAX(TODAY()-N7,0)),0) -> 0 | R7: =IF(B7="","",IF(G7=0,"COMPLETO",IF(G7<=D7*0.1,"CASI COMPLETO","PENDIENTE"))) -> PENDIENTE | S7: =IF(B7="","",IFERROR(F7/D7,0)) -> 0.58333333 | T7: =IF(B7="","",IF(Q7>30,"CRITICO",IF(Q7>7,"URGENTE","NORMAL"))) -> NORMAL
B8: SU115774 | C8: ANILLO RETÉN | D8: 4 | E8: UND | F8: 0 | G8: 4 | H8: 60598.23 | I8: VOLVO GROUP COLOMBIA S A S | J8: 8148471 | K8: CRISTHIAN BENITEZ | L8: 12330019 | M8: 46098 | N8: 46098 | O8: 46054.65 | P8: =IFERROR(G8*H8,0) -> 242392.92 | Q8: =IFERROR(IF(N8="","",MAX(TODAY()-N8,0)),0) -> 21 | R8: =IF(B8="","",IF(G8=0,"COMPLETO",IF(G8<=D8*0.1,"CASI COMPLETO","PENDIENTE"))) -> PENDIENTE | S8: =IF(B8="","",IFERROR(F8/D8,0)) -> 0 | T8: =IF(B8="","",IF(Q8>30,"CRITICO",IF(Q8>7,"URGENTE","NORMAL"))) -> URGENTE
B9: SU115845 | C9: TUERCA DE SUJECION FUELLE NEUMATICO | D9: 2 | E9: UND | F9: 0 | G9: 2 | H9: 6417.9 | I9: VOLVO GROUP COLOMBIA S A S | J9: 990943 | K9: CRISTHIAN BENITEZ | L9: 72601008 | M9: 46106 | N9: 46106 | O9: 2438.802 | P9: =IFERROR(G9*H9,0) -> 12835.8 | Q9: =IFERROR(IF(N9="","",MAX(TODAY()-N9,0)),0) -> 13 | R9: =IF(B9="","",IF(G9=0,"COMPLETO",IF(G9<=D9*0.1,"CASI COMPLETO","PENDIENTE"))) -> PENDIENTE | S9: =IF(B9="","",IFERROR(F9/D9,0)) -> 0 | T9: =IF(B9="","",IF(Q9>30,"CRITICO",IF(Q9>7,"URGENTE","NORMAL"))) -> URGENTE
B10: SU115897 | C10: VALVULA EPG | D10: 1 | E10: UND | F10: 0 | G10: 1 | H10: 1027415 | I10: VOLVO GROUP COLOMBIA S A S | J10: 24122364 | K10: CRISTHIAN BENITEZ | L10: 12540034 | M10: 46109 | N10: 46109 | O10: 195208.9 | P10: =IFERROR(G10*H10,0) -> 1027415 | Q10: =IFERROR(IF(N10="","",MAX(TODAY()-N10,0)),0) -> 10 | R10: =IF(B10="","",IF(G10=0,"COMPLETO",IF(G10<=D10*0.1,"CASI COMPLETO","PENDIENTE"))) -> PENDIENTE | S10: =IF(B10="","",IFERROR(F10/D10,0)) -> 0 | T10: =IF(B10="","",IF(Q10>30,"CRITICO",IF(Q10>7,"URGENTE","NORMAL"))) -> URGENTE
B11: SU115905 | C11: FILTRO DE PARTICULAS | D11: 4 | E11: UND | F11: 3 | G11: 1 | H11: 630000 | I11: VOLVO GROUP COLOMBIA S A S | J11: 21068809 | K11: CHARLY HUERTAS | L11: 12540004-R | M11: 46117 | N11: 46108 | O11: 478800 | P11: =IFERROR(G11*H11,0) -> 630000 | Q11: =IFERROR(IF(N11="","",MAX(TODAY()-N11,0)),0) -> 11 | R11: =IF(B11="","",IF(G11=0,"COMPLETO",IF(G11<=D11*0.1,"CASI COMPLETO","PENDIENTE"))) -> PENDIENTE | S11: =IF(B11="","",IFERROR(F11/D11,0)) -> 0.75 | T11: =IF(B11="","",IF(Q11>30,"CRITICO",IF(Q11>7,"URGENTE","NORMAL"))) -> URGENTE
B12: SU115941 | C12: MANGUITO INYECTOR (CAMISILLA) | D12: 60 | E12: UND | F12: 0 | G12: 60 | H12: 100898.6 | I12: VOLVO GROUP COLOMBIA S A S | J12: 21351717 | K12: CRISTHIAN BENITEZ | L12: 12110008 | M12: 46118 | N12: 46108 | O12: 1150244 | P12: =IFERROR(G12*H12,0) -> 6053916 | Q12: =IFERROR(IF(N12="","",MAX(TODAY()-N12,0)),0) -> 11 | R12: =IF(B12="","",IF(G12=0,"COMPLETO",IF(G12<=D12*0.1,"CASI COMPLETO","PENDIENTE"))) -> PENDIENTE | S12: =IF(B12="","",IFERROR(F12/D12,0)) -> 0 | T12: =IF(B12="","",IF(Q12>30,"CRITICO",IF(Q12>7,"URGENTE","NORMAL"))) -> URGENTE
B13: SU115941 | C13: MANGUERA DE REFRIGERACION RADIADOR | D13: 40 | E13: UND | F13: 0 | G13: 40 | H13: 141368.9 | I13: VOLVO GROUP COLOMBIA S A S | J13: 22129907 | K13: CRISTHIAN BENITEZ | L13: 12630024 | M13: 46118 | N13: 46108 | O13: 1074404 | P13: =IFERROR(G13*H13,0) -> 5654756 | Q13: =IFERROR(IF(N13="","",MAX(TODAY()-N13,0)),0) -> 11 | R13: =IF(B13="","",IF(G13=0,"COMPLETO",IF(G13<=D13*0.1,"CASI COMPLETO","PENDIENTE"))) -> PENDIENTE | S13: =IF(B13="","",IFERROR(F13/D13,0)) -> 0 | T13: =IF(B13="","",IF(Q13>30,"CRITICO",IF(Q13>7,"URGENTE","NORMAL"))) -> URGENTE
B14: SU115941 | C14: MANGUERA DE REFRIGERACION RADIADOR | D14: 60 | E14: UND | F14: 0 | G14: 60 | H14: 133053.1 | I14: VOLVO GROUP COLOMBIA S A S | J14: 22129120 | K14: CRISTHIAN BENITEZ | L14: 12630025 | M14: 46118 | N14: 46108 | O14: 1516806 | P14: =IFERROR(G14*H14,0) -> 7983186 | Q14: =IFERROR(IF(N14="","",MAX(TODAY()-N14,0)),0) -> 11 | R14: =IF(B14="","",IF(G14=0,"COMPLETO",IF(G14<=D14*0.1,"CASI COMPLETO","PENDIENTE"))) -> PENDIENTE | S14: =IF(B14="","",IFERROR(F14/D14,0)) -> 0 | T14: =IF(B14="","",IF(Q14>30,"CRITICO",IF(Q14>7,"URGENTE","NORMAL"))) -> URGENTE
B15: SU115941 | C15: MANGUERA DE REFRIGERACION COMPRESOR ØEXT 18MM ØINT 13MM | D15: 40 | E15: UND | F15: 0 | G15: 40 | H15: 69298.5 | I15: VOLVO GROUP COLOMBIA S A S | J15: 21339891 | K15: CRISTHIAN BENITEZ | L15: 12630027 | M15: 46118 | N15: 46108 | O15: 526668.6 | P15: =IFERROR(G15*H15,0) -> 2771940 | Q15: =IFERROR(IF(N15="","",MAX(TODAY()-N15,0)),0) -> 11 | R15: =IF(B15="","",IF(G15=0,"COMPLETO",IF(G15<=D15*0.1,"CASI COMPLETO","PENDIENTE"))) -> PENDIENTE | S15: =IF(B15="","",IFERROR(F15/D15,0)) -> 0 | T15: =IF(B15="","",IF(Q15>30,"CRITICO",IF(Q15>7,"URGENTE","NORMAL"))) -> URGENTE
B16: SU115941 | C16: MANGUERA DE UNION LARGA | D16: 30 | E16: UND | F16: 0 | G16: 30 | H16: 97017.9 | I16: VOLVO GROUP COLOMBIA S A S | J16: 22417892 | K16: CRISTHIAN BENITEZ | L16: 12630028 | M16: 46118 | N16: 46108 | O16: 553002 | P16: =IFERROR(G16*H16,0) -> 2910537 | Q16: =IFERROR(IF(N16="","",MAX(TODAY()-N16,0)),0) -> 11 | R16: =IF(B16="","",IF(G16=0,"COMPLETO",IF(G16<=D16*0.1,"CASI COMPLETO","PENDIENTE"))) -> PENDIENTE | S16: =IF(B16="","",IFERROR(F16/D16,0)) -> 0 | T16: =IF(B16="","",IF(Q16>30,"CRITICO",IF(Q16>7,"URGENTE","NORMAL"))) -> URGENTE
B17: SU115941 | C17: MANGUERA DE UNION CORTA | D17: 120 | E17: UND | F17: 0 | G17: 120 | H17: 77614.32 | I17: VOLVO GROUP COLOMBIA S A S | J17: 24288019 | K17: CRISTHIAN BENITEZ | L17: 12630029 | M17: 46118 | N17: 46108 | O17: 1769606 | P17: =IFERROR(G17*H17,0) -> 9313718.4 | Q17: =IFERROR(IF(N17="","",MAX(TODAY()-N17,0)),0) -> 11 | R17: =IF(B17="","",IF(G17=0,"COMPLETO",IF(G17<=D17*0.1,"CASI COMPLETO","PENDIENTE"))) -> PENDIENTE | S17: =IF(B17="","",IFERROR(F17/D17,0)) -> 0 | T17: =IF(B17="","",IF(Q17>30,"CRITICO",IF(Q17>7,"URGENTE","NORMAL"))) -> URGENTE
B18: SU115941 | C18: MANGUERA EN S TANQUE DE EXPANSION | D18: 60 | E18: UND | F18: 0 | G18: 60 | H18: 83158.2 | I18: VOLVO GROUP COLOMBIA S A S | J18: 22420663 | K18: CRISTHIAN BENITEZ | L18: 12630031 | M18: 46118 | N18: 46108 | O18: 948003.5 | P18: =IFERROR(G18*H18,0) -> 4989492 | Q18: =IFERROR(IF(N18="","",MAX(TODAY()-N18,0)),0) -> 11 | R18: =IF(B18="","",IF(G18=0,"COMPLETO",IF(G18<=D18*0.1,"CASI COMPLETO","PENDIENTE"))) -> PENDIENTE | S18: =IF(B18="","",IFERROR(F18/D18,0)) -> 0 | T18: =IF(B18="","",IF(Q18>30,"CRITICO",IF(Q18>7,"URGENTE","NORMAL"))) -> URGENTE
B19: SU115941 | C19: ABRAZADERA DE MANGUERA CON TORNILLO SINFÍN Ø 75MM | D19: 100 | E19: UND | F19: 0 | G19: 100 | H19: 6763.53 | I19: VOLVO GROUP COLOMBIA S A S | J19: 994565 | K19: CRISTHIAN BENITEZ | L19: 12630033 | M19: 46118 | N19: 46108 | O19: 128507.1 | P19: =IFERROR(G19*H19,0) -> 676353 | Q19: =IFERROR(IF(N19="","",MAX(TODAY()-N19,0)),0) -> 11 | R19: =IF(B19="","",IF(G19=0,"COMPLETO",IF(G19<=D19*0.1,"CASI COMPLETO","PENDIENTE"))) -> PENDIENTE | S19: =IF(B19="","",IFERROR(F19/D19,0)) -> 0 | T19: =IF(B19="","",IF(Q19>30,"CRITICO",IF(Q19>7,"URGENTE","NORMAL"))) -> URGENTE
B20: SU115941 | C20: ABRAZADERA DE MANGUERA CON TORNILLO SINFÍN Ø 66MM | D20: 600 | E20: UND | F20: 0 | G20: 600 | H20: 5904.23 | I20: VOLVO GROUP COLOMBIA S A S | J20: 994564 | K20: CRISTHIAN BENITEZ | L20: 12630034 | M20: 46118 | N20: 46108 | O20: 673082.2 | P20: =IFERROR(G20*H20,0) -> 3542538 | Q20: =IFERROR(IF(N20="","",MAX(TODAY()-N20,0)),0) -> 11 | R20: =IF(B20="","",IF(G20=0,"COMPLETO",IF(G20<=D20*0.1,"CASI COMPLETO","PENDIENTE"))) -> PENDIENTE | S20: =IF(B20="","",IFERROR(F20/D20,0)) -> 0 | T20: =IF(B20="","",IF(Q20>30,"CRITICO",IF(Q20>7,"URGENTE","NORMAL"))) -> URGENTE
B21: SU115941 | C21: ABRAZADERA DE MANGUERA CON TORNILLO SINFÍN Ø 15MM | D21: 300 | E21: UND | F21: 0 | G21: 300 | H21: 4241.07 | I21: VOLVO GROUP COLOMBIA S A S | J21: 994557 | K21: CRISTHIAN BENITEZ | L21: 12630035 | M21: 46118 | N21: 46108 | O21: 241741 | P21: =IFERROR(G21*H21,0) -> 1272321 | Q21: =IFERROR(IF(N21="","",MAX(TODAY()-N21,0)),0) -> 11 | R21: =IF(B21="","",IF(G21=0,"COMPLETO",IF(G21<=D21*0.1,"CASI COMPLETO","PENDIENTE"))) -> PENDIENTE | S21: =IF(B21="","",IFERROR(F21/D21,0)) -> 0 | T21: =IF(B21="","",IF(Q21>30,"CRITICO",IF(Q21>7,"URGENTE","NORMAL"))) -> URGENTE
B22: SU115941 | C22: ABRAZADERA DE MANGUERA CON TORNILLO SINFÍN Ø 45MM | D22: 120 | E22: UND | F22: 0 | G22: 120 | H22: 7317.92 | I22: VOLVO GROUP COLOMBIA S A S | J22: 984996 | K22: CRISTHIAN BENITEZ | L22: 12630036 | M22: 46118 | N22: 46108 | O22: 166848.6 | P22: =IFERROR(G22*H22,0) -> 878150.4 | Q22: =IFERROR(IF(N22="","",MAX(TODAY()-N22,0)),0) -> 11 | R22: =IF(B22="","",IF(G22=0,"COMPLETO",IF(G22<=D22*0.1,"CASI COMPLETO","PENDIENTE"))) -> PENDIENTE | S22: =IF(B22="","",IFERROR(F22/D22,0)) -> 0 | T22: =IF(B22="","",IF(Q22>30,"CRITICO",IF(Q22>7,"URGENTE","NORMAL"))) -> URGENTE
B23: SU115941 | C23: ABRAZADERA DE MANGUERA CON TORNILLO SINFÍN Ø 22MM | D23: 600 | E23: UND | F23: 0 | G23: 600 | H23: 5128.09 | I23: VOLVO GROUP COLOMBIA S A S | J23: 984993 | K23: CRISTHIAN BENITEZ | L23: 12630037 | M23: 46118 | N23: 46108 | O23: 584602.3 | P23: =IFERROR(G23*H23,0) -> 3076854 | Q23: =IFERROR(IF(N23="","",MAX(TODAY()-N23,0)),0) -> 11 | R23: =IF(B23="","",IF(G23=0,"COMPLETO",IF(G23<=D23*0.1,"CASI COMPLETO","PENDIENTE"))) -> PENDIENTE | S23: =IF(B23="","",IFERROR(F23/D23,0)) -> 0 | T23: =IF(B23="","",IF(Q23>30,"CRITICO",IF(Q23>7,"URGENTE","NORMAL"))) -> URGENTE
... B45: SU115951 | C45: TORNILLO EMBRIDADO M10*80 MM | D45: 5 | E45: UND | F45: 0 | G45: 5 | H45: 10533.37 | I45: VOLVO GROUP COLOMBIA S A S | J45: 984759 | K45: CRISTHIAN BENITEZ | L45: 2150209 | M45: 46122 | N45: 46120 | O45: 10006.7 | P45: =IFERROR(G45*H45,0) -> 52666.85 | Q45: =IFERROR(IF(N45="","",MAX(TODAY()-N45,0)),0) -> 0 | R45: =IF(B45="","",IF(G45=0,"COMPLETO",IF(G45<=D45*0.1,"CASI COMPLETO","PENDIENTE"))) -> PENDIENTE | S45: =IF(B45="","",IFERROR(F45/D45,0)) -> 0 | T45: =IF(B45="","",IF(Q45>30,"CRITICO",IF(Q45>7,"URGENTE","NORMAL"))) -> NORMAL
B46: SU115877 | C46: PERFIL PLASTICO AMARILLO | D46: 90 | E46: M | F46: 0 | G46: 90 | H46: 4700 | I46: UNIVERSAL DE PARTES Y REPUESTOS SAS | K46: CRISTHIAN BENITEZ | L46: 80130010 | M46: 46113 | N46: 46113 | O46: 80370 | P46: =IFERROR(G46*H46,0) -> 423000 | Q46: =IFERROR(IF(N46="","",MAX(TODAY()-N46,0)),0) -> 6 | R46: =IF(B46="","",IF(G46=0,"COMPLETO",IF(G46<=D46*0.1,"CASI COMPLETO","PENDIENTE"))) -> PENDIENTE | S46: =IF(B46="","",IFERROR(F46/D46,0)) -> 0 | T46: =IF(B46="","",IF(Q46>30,"CRITICO",IF(Q46>7,"URGENTE","NORMAL"))) -> NORMAL
B47: SU115877 | C47: ALMA (LAMINA) CAUCHO REDONDO ARTICULACIÓN | D47: 25 | E47: UND | F47: 12 | G47: 13 | H47: 22000 | I47: UNIVERSAL DE PARTES Y REPUESTOS SAS | K47: CRISTHIAN BENITEZ | L47: 801702026 | M47: 46113 | N47: 46113 | O47: 104500 | P47: =IFERROR(G47*H47,0) -> 286000 | Q47: =IFERROR(IF(N47="","",MAX(TODAY()-N47,0)),0) -> 6 | R47: =IF(B47="","",IF(G47=0,"COMPLETO",IF(G47<=D47*0.1,"CASI COMPLETO","PENDIENTE"))) -> PENDIENTE | S47: =IF(B47="","",IFERROR(F47/D47,0)) -> 0.48 | T47: =IF(B47="","",IF(Q47>30,"CRITICO",IF(Q47>7,"URGENTE","NORMAL"))) -> NORMAL
B48: SU115916 | C48: CORAZA DE 3/4" | D48: 60 | E48: M | F48: 0 | G48: 60 | H48: 1540 | I48: UNIVERSAL DE PARTES Y REPUESTOS SAS | J48: 2242 | K48: CRISTHIAN BENITEZ | L48: 80150077 | M48: 46116 | N48: 46108 | O48: 17556 | P48: =IFERROR(G48*H48,0) -> 92400 | Q48: =IFERROR(IF(N48="","",MAX(TODAY()-N48,0)),0) -> 11 | R48: =IF(B48="","",IF(G48=0,"COMPLETO",IF(G48<=D48*0.1,"CASI COMPLETO","PENDIENTE"))) -> PENDIENTE | S48: =IF(B48="","",IFERROR(F48/D48,0)) -> 0 | T48: =IF(B48="","",IF(Q48>30,"CRITICO",IF(Q48>7,"URGENTE","NORMAL"))) -> URGENTE
B49: SU115551 | C49: TORNILLO TRILOBULAR M8*25 | D49: 200 | E49: UND | F49: 0 | G49: 200 | H49: 700 | I49: TORNOHIMEC SAS | K49: CRISTHIAN BENITEZ | L49: 80110286 | M49: 46085 | N49: 46085 | O49: 26600 | P49: =IFERROR(G49*H49,0) -> 140000 | Q49: =IFERROR(IF(N49="","",MAX(TODAY()-N49,0)),0) -> 34 | R49: =IF(B49="","",IF(G49=0,"COMPLETO",IF(G49<=D49*0.1,"CASI COMPLETO","PENDIENTE"))) -> PENDIENTE | S49: =IF(B49="","",IFERROR(F49/D49,0)) -> 0 | T49: =IF(B49="","",IF(Q49>30,"CRITICO",IF(Q49>7,"URGENTE","NORMAL"))) -> CRITICO
B50: SU115882 | C50: TORNILLO TRILOBULAR M8*25 | D50: 100 | E50: UND | F50: 0 | G50: 100 | H50: 700 | I50: TORNOHIMEC SAS | K50: CRISTHIAN BENITEZ | L50: 80110286 | M50: 46113 | N50: 46113 | O50: 13300 | P50: =IFERROR(G50*H50,0) -> 70000 | Q50: =IFERROR(IF(N50="","",MAX(TODAY()-N50,0)),0) -> 6 | R50: =IF(B50="","",IF(G50=0,"COMPLETO",IF(G50<=D50*0.1,"CASI COMPLETO","PENDIENTE"))) -> PENDIENTE | S50: =IF(B50="","",IFERROR(F50/D50,0)) -> 0 | T50: =IF(B50="","",IF(Q50>30,"CRITICO",IF(Q50>7,"URGENTE","NORMAL"))) -> NORMAL
B51: SU115882 | C51: JUEGO PERFIL TAPA MOTOR | D51: 3 | E51: UND | F51: 0 | G51: 3 | H51: 220000 | I51: TORNOHIMEC SAS | K51: CRISTHIAN BENITEZ | L51: 80130020 | M51: 46113 | N51: 46113 | O51: 125400 | P51: =IFERROR(G51*H51,0) -> 660000 | Q51: =IFERROR(IF(N51="","",MAX(TODAY()-N51,0)),0) -> 6 | R51: =IF(B51="","",IF(G51=0,"COMPLETO",IF(G51<=D51*0.1,"CASI COMPLETO","PENDIENTE"))) -> PENDIENTE | S51: =IF(B51="","",IFERROR(F51/D51,0)) -> 0 | T51: =IF(B51="","",IF(Q51>30,"CRITICO",IF(Q51>7,"URGENTE","NORMAL"))) -> NORMAL
B52: SU115921 | C52: LAMINA GALVANIZADA CALIBRE 14 1,22*2,44 | D52: 1 | E52: UND | F52: 0 | G52: 1 | H52: 340000 | I52: TORNOHIMEC SAS | K52: CRISTHIAN BENITEZ | L52: 80130298 | M52: 46119 | N52: 46113 | O52: 64600 | P52: =IFERROR(G52*H52,0) -> 340000 | Q52: =IFERROR(IF(N52="","",MAX(TODAY()-N52,0)),0) -> 6 | R52: =IF(B52="","",IF(G52=0,"COMPLETO",IF(G52<=D52*0.1,"CASI COMPLETO","PENDIENTE"))) -> PENDIENTE | S52: =IF(B52="","",IFERROR(F52/D52,0)) -> 0 | T52: =IF(B52="","",IF(Q52>30,"CRITICO",IF(Q52>7,"URGENTE","NORMAL"))) -> NORMAL
B53: SU115929 | C53: BRAZO LIMPIAPARABRISAS | D53: 1 | E53: UND | F53: 0 | G53: 1 | H53: 100000 | I53: TORNOHIMEC SAS | K53: CHARLY HUERTAS | L53: 80110014-R | M53: 46122 | N53: 46111 | O53: 19000 | P53: =IFERROR(G53*H53,0) -> 100000 | Q53: =IFERROR(IF(N53="","",MAX(TODAY()-N53,0)),0) -> 8 | R53: =IF(B53="","",IF(G53=0,"COMPLETO",IF(G53<=D53*0.1,"CASI COMPLETO","PENDIENTE"))) -> PENDIENTE | S53: =IF(B53="","",IFERROR(F53/D53,0)) -> 0 | T53: =IF(B53="","",IF(Q53>30,"CRITICO",IF(Q53>7,"URGENTE","NORMAL"))) -> URGENTE
B54: SU115950 | C54: CASQUILLO | D54: 1 | E54: UND | F54: 0 | G54: 1 | H54: 30000 | I54: TORNOHIMEC SAS | K54: CRISTHIAN BENITEZ | L54: 21100014-R | M54: 46122 | N54: 46107 | O54: 5700 | P54: =IFERROR(G54*H54,0) -> 30000 | Q54: =IFERROR(IF(N54="","",MAX(TODAY()-N54,0)),0) -> 12 | R54: =IF(B54="","",IF(G54=0,"COMPLETO",IF(G54<=D54*0.1,"CASI COMPLETO","PENDIENTE"))) -> PENDIENTE | S54: =IF(B54="","",IFERROR(F54/D54,0)) -> 0 | T54: =IF(B54="","",IF(Q54>30,"CRITICO",IF(Q54>7,"URGENTE","NORMAL"))) -> URGENTE
B55: SU111857 | C55: FUELLE NEUMATICO TRASERO | D55: 612 | E55: UND | F55: 502 | G55: 110 | H55: 210000 | I55: TC IMPORTACIONES S.A.S | J55: 954090 | K55: CRISTHIAN BENITEZ | L55: 7260105 | M55: 46037 | N55: 45709 | O55: 24418800 | P55: =IFERROR(G55*H55,0) -> 23100000 | Q55: =IFERROR(IF(N55="","",MAX(TODAY()-N55,0)),0) -> 410 | R55: =IF(B55="","",IF(G55=0,"COMPLETO",IF(G55<=D55*0.1,"CASI COMPLETO","PENDIENTE"))) -> PENDIENTE | S55: =IF(B55="","",IFERROR(F55/D55,0)) -> 0.82026144 | T55: =IF(B55="","",IF(Q55>30,"CRITICO",IF(Q55>7,"URGENTE","NORMAL"))) -> CRITICO
B56: SU111857 | C56: FUELLE NEUMATICO EJE DE REMOLQUE | D56: 500 | E56: UND | F56: 450 | G56: 50 | H56: 173000 | I56: TC IMPORTACIONES S.A.S | J56: 954091 | K56: CRISTHIAN BENITEZ | L56: 7260108 | M56: 46037 | N56: 45709 | O56: 16435000 | P56: =IFERROR(G56*H56,0) -> 8650000 | Q56: =IFERROR(IF(N56="","",MAX(TODAY()-N56,0)),0) -> 410 | R56: =IF(B56="","",IF(G56=0,"COMPLETO",IF(G56<=D56*0.1,"CASI COMPLETO","PENDIENTE"))) -> CASI COMPLETO | S56: =IF(B56="","",IFERROR(F56/D56,0)) -> 0.9 | T56: =IF(B56="","",IF(Q56>30,"CRITICO",IF(Q56>7,"URGENTE","NORMAL"))) -> CRITICO
B57: SU111857 | C57: FUELLE NEUMATICO DELANTERO | D57: 260 | E57: UND | F57: 202 | G57: 58 | H57: 580000 | I57: TC IMPORTACIONES S.A.S | J57: 954089 | K57: CRISTHIAN BENITEZ | L57: 7260200 | M57: 46037 | N57: 45709 | O57: 28652000 | P57: =IFERROR(G57*H57,0) -> 33640000 | Q57: =IFERROR(IF(N57="","",MAX(TODAY()-N57,0)),0) -> 410 | R57: =IF(B57="","",IF(G57=0,"COMPLETO",IF(G57<=D57*0.1,"CASI COMPLETO","PENDIENTE"))) -> PENDIENTE | S57: =IF(B57="","",IFERROR(F57/D57,0)) -> 0.77692308 | T57: =IF(B57="","",IF(Q57>30,"CRITICO",IF(Q57>7,"URGENTE","NORMAL"))) -> CRITICO
B58: SU115560 | C58: CANTONERA PUERTA DE SERVICIO IZQUIERDA | D58: 3 | E58: UND | F58: 0 | G58: 3 | H58: 28487 | I58: SUPERPOLO S.A.S | J58: 11431971 | K58: CRISTHIAN BENITEZ | L58: 80110264 | M58: 46079 | N58: 46072 | O58: 16237.59 | P58: =IFERROR(G58*H58,0) -> 85461 | Q58: =IFERROR(IF(N58="","",MAX(TODAY()-N58,0)),0) -> 47 | R58: =IF(B58="","",IF(G58=0,"COMPLETO",IF(G58<=D58*0.1,"CASI COMPLETO","PENDIENTE"))) -> PENDIENTE | S58: =IF(B58="","",IFERROR(F58/D58,0)) -> 0 | T58: =IF(B58="","",IF(Q58>30,"CRITICO",IF(Q58>7,"URGENTE","NORMAL"))) -> CRITICO
B59: SU115924 | C59: BOOSTER DE PUERTA DE SERVICIO | D59: 1 | E59: UND | F59: 0 | G59: 1 | H59: 321023.9 | I59: SUPERPOLO S.A.S | J59: 26246687 | K59: CRISTHIAN BENITEZ | L59: 80110118 | M59: 46121 | N59: 46113 | O59: 60994.54 | P59: =IFERROR(G59*H59,0) -> 321023.9 | Q59: =IFERROR(IF(N59="","",MAX(TODAY()-N59,0)),0) -> 6 | R59: =IF(B59="","",IF(G59=0,"COMPLETO",IF(G59<=D59*0.1,"CASI COMPLETO","PENDIENTE"))) -> PENDIENTE | S59: =IF(B59="","",IFERROR(F59/D59,0)) -> 0 | T59: =IF(B59="","",IF(Q59>30,"CRITICO",IF(Q59>7,"URGENTE","NORMAL"))) -> NORMAL
B60: SU114738 | C60: TORNILLO AVELLANADO M8*1" | D60: 600 | E60: UND | F60: 0 | G60: 600 | H60: 40 | I60: SUMILOGISTICA S.A.S. | J60: 1495 | K60: CRISTHIAN BENITEZ | L60: 80110133 | M60: 45992 | N60: 45992 | O60: 4560 | P60: =IFERROR(G60*H60,0) -> 24000 | Q60: =IFERROR(IF(N60="","",MAX(TODAY()-N60,0)),0) -> 127 | R60: =IF(B60="","",IF(G60=0,"COMPLETO",IF(G60<=D60*0.1,"CASI COMPLETO","PENDIENTE"))) -> PENDIENTE | S60: =IF(B60="","",IFERROR(F60/D60,0)) -> 0 | T60: =IF(B60="","",IF(Q60>30,"CRITICO",IF(Q60>7,"URGENTE","NORMAL"))) -> CRITICO
B61: SU115064 | C61: POLIURETANO AMARILLO PASAMANOS | D61: 16000 | E61: GR | F61: 8000 | G61: 8000 | H61: 72.19 | I61: SUMILOGISTICA S.A.S. | J61: 2491 | K61: CRISTHIAN BENITEZ | L61: 801200119-G | M61: 46265 | N61: 46142 | O61: 219457.6 | P61: =IFERROR(G61*H61,0) -> 577520 | Q61: =IFERROR(IF(N61="","",MAX(TODAY()-N61,0)),0) -> 0 | R61: =IF(B61="","",IF(G61=0,"COMPLETO",IF(G61<=D61*0.1,"CASI COMPLETO","PENDIENTE"))) -> PENDIENTE | S61: =IF(B61="","",IFERROR(F61/D61,0)) -> 0.5 | T61: =IF(B61="","",IF(Q61>30,"CRITICO",IF(Q61>7,"URGENTE","NORMAL"))) -> NORMAL
...

Sheet PENDIENTES DETALLE
A1: DETALLE DE MATERIALES PENDIENTES POR LLEGAR
A2: Control de entregas | Se alimenta de DATA PENDIENTES automaticamente
A3: OC | B3: DESCRIPCION | C3: MAINSAVER | D3: PARTE FABRICANTE | E3: SOLICITADO | F3: UM | G3: RECIBIDO | H3: PENDIENTE | I3: COSTO UNIT. | J3: VALOR PENDIENTE | K3: PROVEEDOR | L3: COMPRADOR | M3: FECHA PROMESA | N3: FECHA REQUERIDA | O3: DIAS RETRASO | P3: ESTADO | Q3: CUMPLIMIENTO | R3: ALERTA | S3: PRIORIDAD | T3: VALOR IMPUESTO
A4: =IF('DATA PENDIENTES'!B45="","",'DATA PENDIENTES'!B45) -> SU115951 | B4: =IF(A4="","",'DATA PENDIENTES'!C45) -> TORNILLO EMBRIDADO M10*80 MM | C4: =IF(A4="","",'DATA PENDIENTES'!L45) -> 2150209 | D4: =IF(A4="","",'DATA PENDIENTES'!J45) -> 984759 | E4: =IF(A4="","",'DATA PENDIENTES'!D45) -> 5 | F4: =IF(A4="","",'DATA PENDIENTES'!E45) -> UND | G4: =IF(A4="","",'DATA PENDIENTES'!F45) -> 0 | H4: =IF(A4="","",'DATA PENDIENTES'!G45) -> 5 | I4: =IF(A4="","",'DATA PENDIENTES'!H45) -> 10533.37 | J4: =IF(A4="","",IFERROR(H4*F4,0)) -> 0 | K4: =IF(A4="","",'DATA PENDIENTES'!I45) -> VOLVO GROUP COLOMBIA S A S | L4: =IF(A4="","",'DATA PENDIENTES'!K45) -> CRISTHIAN BENITEZ | M4: =IF(A4="","",'DATA PENDIENTES'!M45) -> 46122 | N4: =IF(A4="","",'DATA PENDIENTES'!N45) -> 46120 | O4: =IF(A4="","",IFERROR(MAX(TODAY()-N4,0),0)) -> 0 | P4: =IF(A4="","",IF(H4=0,"COMPLETO",IF(H4<=E4*0.1,"CASI COMPLETO","PENDIENTE"))) -> PENDIENTE | Q4: =IF(A4="","",IFERROR(G4/E4,0)) -> 0 | R4: =IF(A4="","",IF(O4>30,"CRITICO",IF(O4>7,"ALERTA","OK"))) -> OK | S4: =IF(A4="","",IF(O4>30,"1-CRITICO",IF(O4>7,"2-URGENTE","3-NORMAL"))) -> 3-NORMAL | T4: =IF(A4="","",'DATA PENDIENTES'!O45) -> 10006.7
A5: =IF('DATA PENDIENTES'!B29="","",'DATA PENDIENTES'!B29) -> SU115941 | B5: =IF(A5="","",'DATA PENDIENTES'!C29) -> FILTRO DE ACEITE MOTOR DE DERIVACION | C5: =IF(A5="","",'DATA PENDIENTES'!L29) -> 2220200 | D5: =IF(A5="","",'DATA PENDIENTES'!J29) -> 21707132 | E5: =IF(A5="","",'DATA PENDIENTES'!D29) -> 40 | F5: =IF(A5="","",'DATA PENDIENTES'!E29) -> UND | G5: =IF(A5="","",'DATA PENDIENTES'!F29) -> 0 | H5: =IF(A5="","",'DATA PENDIENTES'!G29) -> 40 | I5: =IF(A5="","",'DATA PENDIENTES'!H29) -> 47122.98 | J5: =IF(A5="","",IFERROR(H5*F5,0)) -> 0 | K5: =IF(A5="","",'DATA PENDIENTES'!I29) -> VOLVO GROUP COLOMBIA S A S | L5: =IF(A5="","",'DATA PENDIENTES'!K29) -> CRISTHIAN BENITEZ | M5: =IF(A5="","",'DATA PENDIENTES'!M29) -> 46118 | N5: =IF(A5="","",'DATA PENDIENTES'!N29) -> 46108 | O5: =IF(A5="","",IFERROR(MAX(TODAY()-N5,0),0)) -> 11 | P5: =IF(A5="","",IF(H5=0,"COMPLETO",IF(H5<=E5*0.1,"CASI COMPLETO","PENDIENTE"))) -> PENDIENTE | Q5: =IF(A5="","",IFERROR(G5/E5,0)) -> 0 | R5: =IF(A5="","",IF(O5>30,"CRITICO",IF(O5>7,"ALERTA","OK"))) -> ALERTA | S5: =IF(A5="","",IF(O5>30,"1-CRITICO",IF(O5>7,"2-URGENTE","3-NORMAL"))) -> 2-URGENTE | T5: =IF(A5="","",'DATA PENDIENTES'!O29) -> 358134.6
A6: =IF('DATA PENDIENTES'!B30="","",'DATA PENDIENTES'!B30) -> SU115941 | B6: =IF(A6="","",'DATA PENDIENTES'!C30) -> FILTRO DE ACEITE MOTOR LARGA DURACION | C6: =IF(A6="","",'DATA PENDIENTES'!L30) -> 2220201 | D6: =IF(A6="","",'DATA PENDIENTES'!J30) -> 21707133 | E6: =IF(A6="","",'DATA PENDIENTES'!D30) -> 120 | F6: =IF(A6="","",'DATA PENDIENTES'!E30) -> UND | G6: =IF(A6="","",'DATA PENDIENTES'!F30) -> 0 | H6: =IF(A6="","",'DATA PENDIENTES'!G30) -> 120 | I6: =IF(A6="","",'DATA PENDIENTES'!H30) -> 58210.74 | J6: =IF(A6="","",IFERROR(H6*F6,0)) -> 0 | K6: =IF(A6="","",'DATA PENDIENTES'!I30) -> VOLVO GROUP COLOMBIA S A S | L6: =IF(A6="","",'DATA PENDIENTES'!K30) -> CRISTHIAN BENITEZ | M6: =IF(A6="","",'DATA PENDIENTES'!M30) -> 46118 | N6: =IF(A6="","",'DATA PENDIENTES'!N30) -> 46108 | O6: =IF(A6="","",IFERROR(MAX(TODAY()-N6,0),0)) -> 11 | P6: =IF(A6="","",IF(H6=0,"COMPLETO",IF(H6<=E6*0.1,"CASI COMPLETO","PENDIENTE"))) -> PENDIENTE | Q6: =IF(A6="","",IFERROR(G6/E6,0)) -> 0 | R6: =IF(A6="","",IF(O6>30,"CRITICO",IF(O6>7,"ALERTA","OK"))) -> ALERTA | S6: =IF(A6="","",IF(O6>30,"1-CRITICO",IF(O6>7,"2-URGENTE","3-NORMAL"))) -> 2-URGENTE | T6: =IF(A6="","",'DATA PENDIENTES'!O30) -> 1327205
A7: =IF('DATA PENDIENTES'!B31="","",'DATA PENDIENTES'!B31) -> SU115941 | B7: =IF(A7="","",'DATA PENDIENTES'!C31) -> FILTRO DE ACEITE DE TRANSMISION | C7: =IF(A7="","",'DATA PENDIENTES'!L31) -> 2220202 | D7: =IF(A7="","",'DATA PENDIENTES'!J31) -> 22925076 | E7: =IF(A7="","",'DATA PENDIENTES'!D31) -> 15 | F7: =IF(A7="","",'DATA PENDIENTES'!E31) -> UND | G7: =IF(A7="","",'DATA PENDIENTES'!F31) -> 0 | H7: =IF(A7="","",'DATA PENDIENTES'!G31) -> 15 | I7: =IF(A7="","",'DATA PENDIENTES'!H31) -> 210667.4 | J7: =IF(A7="","",IFERROR(H7*F7,0)) -> 0 | K7: =IF(A7="","",'DATA PENDIENTES'!I31) -> VOLVO GROUP COLOMBIA S A S | L7: =IF(A7="","",'DATA PENDIENTES'!K31) -> CRISTHIAN BENITEZ | M7: =IF(A7="","",'DATA PENDIENTES'!M31) -> 46118 | N7: =IF(A7="","",'DATA PENDIENTES'!N31) -> 46108 | O7: =IF(A7="","",IFERROR(MAX(TODAY()-N7,0),0)) -> 11 | P7: =IF(A7="","",IF(H7=0,"COMPLETO",IF(H7<=E7*0.1,"CASI COMPLETO","PENDIENTE"))) -> PENDIENTE | Q7: =IF(A7="","",IFERROR(G7/E7,0)) -> 0 | R7: =IF(A7="","",IF(O7>30,"CRITICO",IF(O7>7,"ALERTA","OK"))) -> ALERTA | S7: =IF(A7="","",IF(O7>30,"1-CRITICO",IF(O7>7,"2-URGENTE","3-NORMAL"))) -> 2-URGENTE | T7: =IF(A7="","",'DATA PENDIENTES'!O31) -> 600402.2
A8: =IF('DATA PENDIENTES'!B32="","",'DATA PENDIENTES'!B32) -> SU115941 | B8: =IF(A8="","",'DATA PENDIENTES'!C32) -> FILTRO DE COMBUSTIBLE SEPARADOR DE AGUA | C8: =IF(A8="","",'DATA PENDIENTES'!L32) -> 2330201 | D8: =IF(A8="","",'DATA PENDIENTES'!J32) -> 20998367 | E8: =IF(A8="","",'DATA PENDIENTES'!D32) -> 60 | F8: =IF(A8="","",'DATA PENDIENTES'!E32) -> UND | G8: =IF(A8="","",'DATA PENDIENTES'!F32) -> 0 | H8: =IF(A8="","",'DATA PENDIENTES'!G32) -> 60 | I8: =IF(A8="","",'DATA PENDIENTES'!H32) -> 66526.56 | J8: =IF(A8="","",IFERROR(H8*F8,0)) -> 0 | K8: =IF(A8="","",'DATA PENDIENTES'!I32) -> VOLVO GROUP COLOMBIA S A S | L8: =IF(A8="","",'DATA PENDIENTES'!K32) -> CRISTHIAN BENITEZ | M8: =IF(A8="","",'DATA PENDIENTES'!M32) -> 46118 | N8: =IF(A8="","",'DATA PENDIENTES'!N32) -> 46108 | O8: =IF(A8="","",IFERROR(MAX(TODAY()-N8,0),0)) -> 11 | P8: =IF(A8="","",IF(H8=0,"COMPLETO",IF(H8<=E8*0.1,"CASI COMPLETO","PENDIENTE"))) -> PENDIENTE | Q8: =IF(A8="","",IFERROR(G8/E8,0)) -> 0 | R8: =IF(A8="","",IF(O8>30,"CRITICO",IF(O8>7,"ALERTA","OK"))) -> ALERTA | S8: =IF(A8="","",IF(O8>30,"1-CRITICO",IF(O8>7,"2-URGENTE","3-NORMAL"))) -> 2-URGENTE | T8: =IF(A8="","",'DATA PENDIENTES'!O32) -> 758402.8
A9: =IF('DATA PENDIENTES'!B33="","",'DATA PENDIENTES'!B33) -> SU115941 | B9: =IF(A9="","",'DATA PENDIENTES'!C33) -> FILTRO DE COMBUSTIBLE | C9: =IF(A9="","",'DATA PENDIENTES'!L33) -> 2330207 | D9: =IF(A9="","",'DATA PENDIENTES'!J33) -> 22480372 | E9: =IF(A9="","",'DATA PENDIENTES'!D33) -> 60 | F9: =IF(A9="","",'DATA PENDIENTES'!E33) -> UND | G9: =IF(A9="","",'DATA PENDIENTES'!F33) -> 0 | H9: =IF(A9="","",'DATA PENDIENTES'!G33) -> 60 | I9: =IF(A9="","",'DATA PENDIENTES'!H33) -> 58210.74 | J9: =IF(A9="","",IFERROR(H9*F9,0)) -> 0 | K9: =IF(A9="","",'DATA PENDIENTES'!I33) -> VOLVO GROUP COLOMBIA S A S | L9: =IF(A9="","",'DATA PENDIENTES'!K33) -> CRISTHIAN BENITEZ | M9: =IF(A9="","",'DATA PENDIENTES'!M33) -> 46118 | N9: =IF(A9="","",'DATA PENDIENTES'!N33) -> 46108 | O9: =IF(A9="","",IFERROR(MAX(TODAY()-N9,0),0)) -> 11 | P9: =IF(A9="","",IF(H9=0,"COMPLETO",IF(H9<=E9*0.1,"CASI COMPLETO","PENDIENTE"))) -> PENDIENTE | Q9: =IF(A9="","",IFERROR(G9/E9,0)) -> 0 | R9: =IF(A9="","",IF(O9>30,"CRITICO",IF(O9>7,"ALERTA","OK"))) -> ALERTA | S9: =IF(A9="","",IF(O9>30,"1-CRITICO",IF(O9>7,"2-URGENTE","3-NORMAL"))) -> 2-URGENTE | T9: =IF(A9="","",'DATA PENDIENTES'!O33) -> 663602.4
A10: =IF('DATA PENDIENTES'!B34="","",'DATA PENDIENTES'!B34) -> SU115941 | B10: =IF(A10="","",'DATA PENDIENTES'!C34) -> FILTRO RESPIRADERO TANQUE DE COMBUSTIBLE | C10: =IF(A10="","",'DATA PENDIENTES'!L34) -> 2330209 | D10: =IF(A10="","",'DATA PENDIENTES'!J34) -> 21743197 | E10: =IF(A10="","",'DATA PENDIENTES'!D34) -> 20 | F10: =IF(A10="","",'DATA PENDIENTES'!E34) -> UND | G10: =IF(A10="","",'DATA PENDIENTES'!F34) -> 0 | H10: =IF(A10="","",'DATA PENDIENTES'!G34) -> 20 | I10: =IF(A10="","",'DATA PENDIENTES'!H34) -> 83158.2 | J10: =IF(A10="","",IFERROR(H10*F10,0)) -> 0 | K10: =IF(A10="","",'DATA PENDIENTES'!I34) -> VOLVO GROUP COLOMBIA S A S | L10: =IF(A10="","",'DATA PENDIENTES'!K34) -> CRISTHIAN BENITEZ | M10: =IF(A10="","",'DATA PENDIENTES'!M34) -> 46118 | N10: =IF(A10="","",'DATA PENDIENTES'!N34) -> 46108 | O10: =IF(A10="","",IFERROR(MAX(TODAY()-N10,0),0)) -> 11 | P10: =IF(A10="","",IF(H10=0,"COMPLETO",IF(H10<=E10*0.1,"CASI COMPLETO","PENDIENTE"))) -> PENDIENTE | Q10: =IF(A10="","",IFERROR(G10/E10,0)) -> 0 | R10: =IF(A10="","",IF(O10>30,"CRITICO",IF(O10>7,"ALERTA","OK"))) -> ALERTA | S10: =IF(A10="","",IF(O10>30,"1-CRITICO",IF(O10>7,"2-URGENTE","3-NORMAL"))) -> 2-URGENTE | T10: =IF(A10="","",'DATA PENDIENTES'!O34) -> 316001.2
A11: =IF('DATA PENDIENTES'!B178="","",'DATA PENDIENTES'!B178) -> SU114612 | B11: =IF(A11="","",'DATA PENDIENTES'!C178) -> ADBLUE ARLA 32 AUTOMOTRIZ | C11: =IF(A11="","",'DATA PENDIENTES'!L178) -> 2540131 | D11: =IF(A11="","",'DATA PENDIENTES'!J178) -> 2540131 | E11: =IF(A11="","",'DATA PENDIENTES'!D178) -> 40000 | F11: =IF(A11="","",'DATA PENDIENTES'!E178) -> L | G11: =IF(A11="","",'DATA PENDIENTES'!F178) -> 30000 | H11: =IF(A11="","",'DATA PENDIENTES'!G178) -> 10000 | I11: =IF(A11="","",'DATA PENDIENTES'!H178) -> 2600 | J11: =IF(A11="","",IFERROR(H11*F11,0)) -> 0 | K11: =IF(A11="","",'DATA PENDIENTES'!I178) -> HIDROTECNIK S A S | L11: =IF(A11="","",'DATA PENDIENTES'!K178) -> CRISTHIAN BENITEZ | M11: =IF(A11="","",'DATA PENDIENTES'!M178) -> 46022 | N11: =IF(A11="","",'DATA PENDIENTES'!N178) -> 45972 | O11: =IF(A11="","",IFERROR(MAX(TODAY()-N11,0),0)) -> 147 | P11: =IF(A11="","",IF(H11=0,"COMPLETO",IF(H11<=E11*0.1,"CASI COMPLETO","PENDIENTE"))) -> PENDIENTE | Q11: =IF(A11="","",IFERROR(G11/E11,0)) -> 0.75 | R11: =IF(A11="","",IF(O11>30,"CRITICO",IF(O11>7,"ALERTA","OK"))) -> CRITICO | S11: =IF(A11="","",IF(O11>30,"1-CRITICO",IF(O11>7,"2-URGENTE","3-NORMAL"))) -> 1-CRITICO | T11: =IF(A11="","",'DATA PENDIENTES'!O178) -> 19760000
A12: =IF('DATA PENDIENTES'!B179="","",'DATA PENDIENTES'!B179) -> SU115621 | B12: =IF(A12="","",'DATA PENDIENTES'!C179) -> ADBLUE ARLA 32 AUTOMOTRIZ | C12: =IF(A12="","",'DATA PENDIENTES'!L179) -> 2540131 | D12: =IF(A12="","",'DATA PENDIENTES'!J179) -> 400205 | E12: =IF(A12="","",'DATA PENDIENTES'!D179) -> 40000 | F12: =IF(A12="","",'DATA PENDIENTES'!E179) -> L | G12: =IF(A12="","",'DATA PENDIENTES'!F179) -> 20000 | H12: =IF(A12="","",'DATA PENDIENTES'!G179) -> 20000 | I12: =IF(A12="","",'DATA PENDIENTES'!H179) -> 2600 | J12: =IF(A12="","",IFERROR(H12*F12,0)) -> 0 | K12: =IF(A12="","",'DATA PENDIENTES'!I179) -> HIDROTECNIK S A S | L12: =IF(A12="","",'DATA PENDIENTES'!K179) -> CRISTHIAN BENITEZ | M12: =IF(A12="","",'DATA PENDIENTES'!M179) -> 46109 | N12: =IF(A12="","",'DATA PENDIENTES'!N179) -> 46079 | O12: =IF(A12="","",IFERROR(MAX(TODAY()-N12,0),0)) -> 40 | P12: =IF(A12="","",IF(H12=0,"COMPLETO",IF(H12<=E12*0.1,"CASI COMPLETO","PENDIENTE"))) -> PENDIENTE | Q12: =IF(A12="","",IFERROR(G12/E12,0)) -> 0.5 | R12: =IF(A12="","",IF(O12>30,"CRITICO",IF(O12>7,"ALERTA","OK"))) -> CRITICO | S12: =IF(A12="","",IF(O12>30,"1-CRITICO",IF(O12>7,"2-URGENTE","3-NORMAL"))) -> 1-CRITICO | T12: =IF(A12="","",'DATA PENDIENTES'!O179) -> 19760000
A13: =IF('DATA PENDIENTES'!B37="","",'DATA PENDIENTES'!B37) -> SU115941 | B13: =IF(A13="","",'DATA PENDIENTES'!C37) -> FILTRO DE HIDRAULICO VENTILADOR | C13: =IF(A13="","",'DATA PENDIENTES'!L37) -> 2630125 | D13: =IF(A13="","",'DATA PENDIENTES'!J37) -> 20801559 | E13: =IF(A13="","",'DATA PENDIENTES'!D37) -> 5 | F13: =IF(A13="","",'DATA PENDIENTES'!E37) -> UND | G13: =IF(A13="","",'DATA PENDIENTES'!F37) -> 0 | H13: =IF(A13="","",'DATA PENDIENTES'!G37) -> 5 | I13: =IF(A13="","",'DATA PENDIENTES'!H37) -> 174632.2 | J13: =IF(A13="","",IFERROR(H13*F13,0)) -> 0 | K13: =IF(A13="","",'DATA PENDIENTES'!I37) -> VOLVO GROUP COLOMBIA S A S | L13: =IF(A13="","",'DATA PENDIENTES'!K37) -> CRISTHIAN BENITEZ | M13: =IF(A13="","",'DATA PENDIENTES'!M37) -> 46118 | N13: =IF(A13="","",'DATA PENDIENTES'!N37) -> 46108 | O13: =IF(A13="","",IFERROR(MAX(TODAY()-N13,0),0)) -> 11 | P13: =IF(A13="","",IF(H13=0,"COMPLETO",IF(H13<=E13*0.1,"CASI COMPLETO","PENDIENTE"))) -> PENDIENTE | Q13: =IF(A13="","",IFERROR(G13/E13,0)) -> 0 | R13: =IF(A13="","",IF(O13>30,"CRITICO",IF(O13>7,"ALERTA","OK"))) -> ALERTA | S13: =IF(A13="","",IF(O13>30,"1-CRITICO",IF(O13>7,"2-URGENTE","3-NORMAL"))) -> 2-URGENTE | T13: =IF(A13="","",'DATA PENDIENTES'!O37) -> 165900.6
A14: =IF('DATA PENDIENTES'!B43="","",'DATA PENDIENTES'!B43) -> SU115942 | B14: =IF(A14="","",'DATA PENDIENTES'!C43) -> TENSOR DE CORREA | C14: =IF(A14="","",'DATA PENDIENTES'!L43) -> 3210113 | D14: =IF(A14="","",'DATA PENDIENTES'!J43) -> 21719386 | E14: =IF(A14="","",'DATA PENDIENTES'!D43) -> 8 | F14: =IF(A14="","",'DATA PENDIENTES'!E43) -> UND | G14: =IF(A14="","",'DATA PENDIENTES'!F43) -> 6 | H14: =IF(A14="","",'DATA PENDIENTES'!G43) -> 2 | I14: =IF(A14="","",'DATA PENDIENTES'!H43) -> 820494.2 | J14: =IF(A14="","",IFERROR(H14*F14,0)) -> 0 | K14: =IF(A14="","",'DATA PENDIENTES'!I43) -> VOLVO GROUP COLOMBIA S A S | L14: =IF(A14="","",'DATA PENDIENTES'!K43) -> CRISTHIAN BENITEZ | M14: =IF(A14="","",'DATA PENDIENTES'!M43) -> 46186 | N14: =IF(A14="","",'DATA PENDIENTES'!N43) -> 46119 | O14: =IF(A14="","",IFERROR(MAX(TODAY()-N14,0),0)) -> 0 | P14: =IF(A14="","",IF(H14=0,"COMPLETO",IF(H14<=E14*0.1,"CASI COMPLETO","PENDIENTE"))) -> PENDIENTE | Q14: =IF(A14="","",IFERROR(G14/E14,0)) -> 0.75 | R14: =IF(A14="","",IF(O14>30,"CRITICO",IF(O14>7,"ALERTA","OK"))) -> OK | S14: =IF(A14="","",IF(O14>30,"1-CRITICO",IF(O14>7,"2-URGENTE","3-NORMAL"))) -> 3-NORMAL | T14: =IF(A14="","",'DATA PENDIENTES'!O43) -> 1247151
